<?xml version="1.0" encoding="UTF-8"?>
<robot xmlns:xacro="http://www.ros.org/wiki/xacro" name="mm">
   <xacro:include filename="mm.gazebo.xacro" />
   <link name="robot_footprint">
      <origin xyz="0 0 0" rpy="0 0 0" />
   </link>
   <joint name="robot_footprint_joint" type="fixed">
      <origin xyz="0 0 0.6" rpy="0 0 0" />
      <parent link="robot_footprint" />
      <child link="chassis" />
   </joint>
   <link name="chassis">
      <pose>0 0 0.1 0 0 0</pose>
      <inertial>
         <mass value="20.0" />
         <origin xyz="0.0 0 0" rpy=" 0 0 0" />
         <inertia ixx="0.1" ixy="0" ixz="0" iyy="0.1" iyz="0" izz="0.1" />
      </inertial>
      <collision name="collision">
         <origin xyz="0 0 0" rpy=" 0 0 0" />
         <geometry>
            <box size=".95 .6 .05" />
         </geometry>
      </collision>
      <visual name="chassis_visual">
         <origin xyz="0 0 0" rpy=" 0 0 0" />
         <geometry>
            <box size=".95 .6 .05" />
         </geometry>
      </visual>
   </link>
   <link name="box">
      <inertial>
         <mass value="20.0" />
         <origin xyz="0.0 0 0" rpy=" 0 0 0" />
         <inertia ixx="0.1" ixy="0" ixz="0" iyy="0.1" iyz="0" izz="0.1" />
      </inertial>
      <collision name="collision">
         <origin xyz="0 0 0.05" rpy=" 0 0 0" />
         <geometry>
            <box size=".7 .5 .35" />
         </geometry>
      </collision>
      <visual name="box_visual">
         <origin xyz="0 0 0.05" rpy=" 0 0 0" />
         <geometry>
            <box size=".7 .5 .35" />
         </geometry>
      </visual>
   </link>
   <joint name="box_joint" type="fixed">
      <origin xyz="0 0 -0.25" rpy="0 0 0" />
      <parent link="chassis" />
      <child link="box" />
   </joint>
   <link name="front_right_wheel">
      <visual name="front_right_wheel_visual">
         <origin xyz="0.0 0 0" rpy=" 0 1.5707 1.5707" />
         <geometry>
            <cylinder length="0.05" radius="0.1" />
         </geometry>
      </visual>
      <collision>
         <origin xyz="0.0 0 0" rpy=" 0 1.5707 1.5707" />
         <geometry>
            <cylinder length="0.05" radius="0.1" />
         </geometry>
      </collision>
      <inertial>
         <origin xyz="0.0 0 0" rpy=" 0 1.5707 1.5707" />
         <mass value="5.0" />
         <inertia ixx="0.1" ixy="0" ixz="0" iyy="0.1" iyz="0" izz="0.1" />
      </inertial>
   </link>
   <link name="back_right_wheel">
      <visual name="back_right_wheel_visual">
         <origin xyz="0.0 0 0" rpy=" 0 1.5707 1.5707" />
         <geometry>
            <cylinder length="0.05" radius="0.2" />
         </geometry>
      </visual>
      <collision>
         <origin xyz="0.0 0 0" rpy=" 0 1.5707 1.5707" />
         <geometry>
            <cylinder length="0.05" radius="0.2" />
         </geometry>
      </collision>
      <inertial>
         <origin xyz="0.0 0 0" rpy=" 0 1.5707 1.5707" />
         <mass value="0.5" />
         <inertia ixx="0.1" ixy="0" ixz="0" iyy="0.1" iyz="0" izz="0.1" />
      </inertial>
   </link>
   <link name="back_right_wheel_cover">
      <visual name="back_right_wheel_cover_visual">
         <origin xyz="0.0 0 0" rpy=" 0 1.5707 1.5707" />
         <geometry>
            <cylinder length="0.01" radius="0.15" />
         </geometry>
      </visual>
      <collision>
         <origin xyz="0.0 0 0" rpy=" 0 1.5707 1.5707" />
         <geometry>
            <cylinder length="0.01" radius="0.15" />
         </geometry>
      </collision>
      <inertial>
         <origin xyz="0.0 0 0" rpy=" 0 1.5707 1.5707" />
         <inertia ixx="0.1" ixy="0" ixz="0" iyy="0.1" iyz="0" izz="0.1" />
         <mass value="0.01" />
      </inertial>
   </link>
   <joint name="front_right_wheel_joint" type="continuous">
      <axis xyz="0 1 0" rpy="0 0 0" />
      <dynamics damping="1.0" friction="1.0" />
      <parent link="chassis" />
      <child link="front_right_wheel" />
      <origin xyz="0.3 -0.3 -0.35" rpy="0 0 0" />
   </joint>
   <joint name="back_right_wheel_joint" type="continuous">
      <axis xyz="0 1 0" rpy="0 0 0" />
      <dynamics damping="1.0" friction="1.0" />
      <parent link="chassis" />
      <child link="back_right_wheel" />
      <origin xyz="-0.25 -0.3 -0.25" rpy="0 0 0" />
   </joint>
   <joint name="back_right_wheel_cover_joint" type="continuous">
      <axis xyz="0 1 0" rpy="0 0 0" />
      <dynamics damping="1.0" friction="1.0" />
      <parent link="back_right_wheel" />
      <child link="back_right_wheel_cover" />
      <origin xyz="0 -0.025 0" rpy="0 0 0" />
   </joint>
   <link name="front_left_wheel">
      <visual name="front_left_wheel_visual">
         <origin xyz="0.0 0 0" rpy=" 0 1.5707 1.5707" />
         <geometry>
            <cylinder length="0.05" radius="0.1" />
         </geometry>
      </visual>
      <collision>
         <origin xyz="0.0 0 0" rpy=" 0 1.5707 1.5707" />
         <geometry>
            <cylinder length="0.05" radius="0.1" />
         </geometry>
      </collision>
      <inertial>
         <origin xyz="0.0 0 0" rpy=" 0 1.5707 1.5707" />
         <mass value="5.0" />
         <inertia ixx="0.1" ixy="0" ixz="0" iyy="0.1" iyz="0" izz="0.1" />
      </inertial>
   </link>
   <link name="back_left_wheel_cover">
      <visual name="back_left_wheel_cover_visual">
         <origin xyz="0.0 0 0" rpy=" 0 1.5707 1.5707" />
         <geometry>
            <cylinder length="0.01" radius="0.15" />
         </geometry>
      </visual>
      <collision>
         <origin xyz="0.0 0 0" rpy=" 0 1.5707 1.5707" />
         <geometry>
            <cylinder length="0.01" radius="0.15" />
         </geometry>
      </collision>
      <inertial>
         <origin xyz="0.0 0 0" rpy=" 0 1.5707 1.5707" />
         <inertia ixx="0.1" ixy="0" ixz="0" iyy="0.1" iyz="0" izz="0.1" />
         <mass value="0.01" />
      </inertial>
   </link>
   <link name="back_left_wheel">
      <visual name="back_left_wheel_visual">
         <origin xyz="0.0 0 0" rpy=" 0 1.5707 1.5707" />
         <geometry>
            <cylinder length="0.05" radius="0.2" />
         </geometry>
      </visual>
      <collision>
         <origin xyz="0.0 0 0" rpy=" 0 1.5707 1.5707" />
         <geometry>
            <cylinder length="0.05" radius="0.2" />
         </geometry>
      </collision>
      <inertial>
         <origin xyz="0.0 0 0" rpy=" 0 1.5707 1.5707" />
         <inertia ixx="0.1" ixy="0" ixz="0" iyy="0.1" iyz="0" izz="0.1" />
         <mass value="0.5" />
      </inertial>
   </link>
   <joint name="front_left_wheel_joint" type="continuous">
      <axis xyz="0 1 0" rpy="0 0 0" />
      <dynamics damping="1.0" friction="1.0" />
      <parent link="chassis" />
      <child link="front_left_wheel" />
      <origin xyz="0.3 0.3 -0.35" rpy="0 0 0" />
   </joint>
   <joint name="back_left_wheel_joint" type="continuous">
      <axis xyz="0 1 0" rpy="0 0 0" />
      <dynamics damping="1.0" friction="1.0" />
      <parent link="chassis" />
      <child link="back_left_wheel" />
      <origin xyz="-0.25 0.3 -0.25" rpy="0 0 0" />
   </joint>
   <joint name="back_left_wheel_cover_joint" type="continuous">
      <axis xyz="0 1 0" rpy="0 0 0" />
      <parent link="back_left_wheel" />
      <child link="back_left_wheel_cover" />
      <origin xyz="0 0.025 0" rpy="0 0 0" />
   </joint>
   <!-- *********************** IMU SENSOR SETUP **********************************  -->
   <joint name="imu_joint" type="fixed">
    <parent link="chassis"/>
    <child link="imu_link"/>
    <origin xyz="0.10 0 0.05" rpy="0 0 0"/>
  </joint>

   <!-- *********************** IMU SENSOR SETUP **************************  -->
  <link name="imu_link"/>
   <!-- *********************** GPS SETUP **********************************  -->
  <joint name="gps_joint" type="fixed">
    <parent link="chassis"/>
    <child link="gps_link"/>
    <origin xyz="0.10 0 0.05" rpy="0 0 0"/>
  </joint>

  <!-- *********************** GPS SETUP *********************************  -->
  <link name="gps_link"/>

   <!-- *********************** LIDAR SETUP **********************************  -->
  <joint name="lidar_joint" type="fixed">
    <parent link="chassis"/>
    <child link="lidar_link"/>
    <origin xyz="0.215 0 0.13" rpy="0 0 0"/>
  </joint>

  <link name="lidar_link">
  
    <collision>
     <origin xyz="0 0 0" rpy="0 0 0"/>
     <geometry>
      <cylinder radius="0.0508" length="0.18"/>
     </geometry>
    </collision>
    
    <visual>
     <origin xyz="0 0 0" rpy="0 0 0"/>
     <geometry>
      <cylinder radius="0.0508" length="0.18"/>
     </geometry>
     <material name="Black">
          <color rgba="${0/255} ${0/255} ${0/255} 1.0"/>
     </material>
    </visual>
    
    <inertial>
      <mass value="0.114" />
      <origin xyz="0 0 0" rpy="0 0 0"/>
      <inertia ixx="0.001" ixy="0" ixz="0" iyy="0.001" iyz="0" izz="0.001" />
    </inertial>
  </link>
   <gazebo reference="chassis">
      <material>Gazebo/White</material>
   </gazebo>
   <gazebo reference="box">
      <material>Gazebo/Grey</material>
   </gazebo>
   <gazebo reference="front_right_wheel">
      <material>Gazebo/Black</material>
   </gazebo>
   <gazebo reference="front_left_wheel">
      <material>Gazebo/Black</material>
   </gazebo>
   <gazebo reference="back_right_wheel">
      <material>Gazebo/Black</material>
   </gazebo>
   <gazebo reference="back_left_wheel">
      <material>Gazebo/Black</material>
   </gazebo>
   <gazebo reference="back_right_wheel_cover">
      <material>Gazebo/Grey</material>
   </gazebo>
   <gazebo reference="back_left_wheel_cover">
      <material>Gazebo/Grey</material>
   </gazebo>
</robot>