<?xml version="1.0" ?>
<!-- =================================================================================== -->
<!-- |    This document was autogenerated by xacro from /home/ubuntu/galactic_ws/src/mm/urdf/mm.urdf.xacro | -->
<!-- |    EDITING THIS FILE BY HAND IS NOT RECOMMENDED                                 | -->
<!-- =================================================================================== -->
<robot name="mm">
  <!--skid_steer_drive_controller-->
  <gazebo>
    <plugin filename="libgazebo_ros_diff_drive.so" name="skid_steer_drive_controller">
      <ros>
        <namespace>/mm</namespace>
        <argument>/cmd_vel:=mr_cme_vel</argument>
        <argument>/odom:=odom</argument>
      </ros>
      <update_rate>100.0</update_rate>
      <odometry_frame>odom</odometry_frame>
      <num_wheel_pairs>2</num_wheel_pairs>
      <robot_base_frame>robot_footprint</robot_base_frame>
      <max_wheel_torque>20</max_wheel_torque>
      <left_joint>front_left_wheel_joint</left_joint>
      <left_joint>back_left_wheel_joint</left_joint>
      <right_joint>front_right_wheel_joint</right_joint>
      <right_joint>back_right_wheel_joint</right_joint>
      <wheel_separation>0.108</wheel_separation>
      <wheel_diameter>0.024</wheel_diameter>
      <publish_wheel_joint_state>true</publish_wheel_joint_state>
      <legacy_mode>false</legacy_mode>
      <publish_odom>true</publish_odom>
      <publish_odom_tf>true</publish_odom_tf>
      <publish_wheel_tf>true</publish_wheel_tf>
      <odometry_source>world</odometry_source>
    </plugin>
  </gazebo>
  <!-- camera -->
  <gazebo reference="camera">
    <sensor name="camera_sensor" type="camera">
      <update_rate>30.0</update_rate>
      <always_on>1</always_on>
      <camera name="camera">
        <horizontal_fov>1.3962634</horizontal_fov>
        <image>
          <width>800</width>
          <height>800</height>
          <format>R8G8B8</format>
        </image>
        <clip>
          <near>0.02</near>
          <far>300</far>
        </clip>
        <distortion>
          <k1>0.0</k1>
          <k2>0.0</k2>
          <k3>0.0</k3>
          <p1>0.0</p1>
          <p2>0.0</p2>
          <center>0.5 0.5</center>
        </distortion>
      </camera>
      <plugin filename="libgazebo_ros_camera.so" name="camera_controller">
        <ros>
          <namespace>/mobot</namespace>
          <argument>camera/image_raw:=/mobot/camera/image</argument>
          <argument>camera/camera_info:=/mobot/camera/image/camera_info</argument>
        </ros>
        <camera_name>camera</camera_name>
        <frame_name>camera</frame_name>
        <hack_baseline>0.07</hack_baseline>
      </plugin>
    </sensor>
  </gazebo>
  <!-- hokuyo -->
  <gazebo reference="lidar_link">
    <sensor name="head_hokuyo_sensor" type="ray">
      <pose>0 0 0 0 0 0</pose>
      <visualize>true</visualize>
      <update_rate>30</update_rate>
      <ray>
        <scan>
          <horizontal>
            <samples>720</samples>
            <resolution>1</resolution>
            <min_angle>-1.570796</min_angle>
            <max_angle>1.570796</max_angle>
          </horizontal>
        </scan>
        <range>
          <min>0.10</min>
          <max>30.0</max>
          <resolution>0.01</resolution>
        </range>
        <noise>
          <type>gaussian</type>
          <!-- Noise parameters based on published spec for Hokuyo laser
                achieving "+-30mm" accuracy at range < 10m.  A mean of 0.0m and
                stddev of 0.01m will put 99.7% of samples within 0.03m of the true
                reading. -->
          <mean>0.0</mean>
          <stddev>0.01</stddev>
        </noise>
      </ray>
      <update_rate>30</update_rate>
      <plugin filename="libgazebo_ros_ray_sensor.so" name="gazebo_ros_head_hokuyo_controller">
        <ros>
          <namespace>/mm</namespace>
          <argument>~/out:=scan</argument>
        </ros>
        <output_type>sensor_msgs/LaserScan</output_type>
      </plugin>
    </sensor>
  </gazebo>
  <!-- gps -->
  <gazebo reference="gps_link">
    <sensor name="bmb_gps" type="gps">
      <always_on>true</always_on>
      <update_rate>10.0</update_rate>
      <gps>
        <position_sensing>
          <horizontal>
            <noise type="gaussian">
              <mean>0.0</mean>
              <stddev>1e-2</stddev>
            </noise>
          </horizontal>
          <vertical>
            <noise type="gaussian">
              <mean>0.0</mean>
              <stddev>1</stddev>
            </noise>
          </vertical>
        </position_sensing>
      </gps>
      <plugin filename="libgazebo_ros_gps_sensor.so" name="basic_mobile_bot_gps">
        <ros>
          <remapping>~/out:=gps/fix</remapping>
        </ros>
      </plugin>
    </sensor>
  </gazebo>
  <gazebo reference="imu_link">
    <gravity>true</gravity>
    <sensor name="bmb_imu" type="imu">
      <always_on>true</always_on>
      <update_rate>100</update_rate>
      <visualize>true</visualize>
      <imu>
        <orientation>
          <x>
            <noise type="gaussian">
              <mean>0.0</mean>
              <stddev>2e-3</stddev>
            </noise>
          </x>
          <y>
            <noise type="gaussian">
              <mean>0.0</mean>
              <stddev>2e-3</stddev>
            </noise>
          </y>
          <z>
            <noise type="gaussian">
              <mean>0.0</mean>
              <stddev>2e-3</stddev>
            </noise>
          </z>
        </orientation>
        <angular_velocity>
          <x>
            <noise type="gaussian">
              <mean>0.0</mean>
              <stddev>2e-4</stddev>
            </noise>
          </x>
          <y>
            <noise type="gaussian">
              <mean>0.0</mean>
              <stddev>2e-4</stddev>
            </noise>
          </y>
          <z>
            <noise type="gaussian">
              <mean>0.0</mean>
              <stddev>2e-4</stddev>
            </noise>
          </z>
        </angular_velocity>
        <linear_acceleration>
          <x>
            <noise type="gaussian">
              <mean>0.0</mean>
              <stddev>1.7e-2</stddev>
            </noise>
          </x>
          <y>
            <noise type="gaussian">
              <mean>0.0</mean>
              <stddev>1.7e-2</stddev>
            </noise>
          </y>
          <z>
            <noise type="gaussian">
              <mean>0.0</mean>
              <stddev>1.7e-2</stddev>
            </noise>
          </z>
        </linear_acceleration>
      </imu>
      <plugin filename="libgazebo_ros_imu_sensor.so" name="basic_mobile_bot_imu">
        <initial_orientation_as_reference>false</initial_orientation_as_reference>
        <frame_name>imu_link</frame_name>
        <ros>
          <namespace>/imu</namespace>
          <remapping>~/out:=data</remapping>
        </ros>
      </plugin>
    </sensor>
  </gazebo>
  <link name="robot_footprint">
    <origin rpy="0 0 0" xyz="0 0 0"/>
  </link>
  <joint name="robot_footprint_joint" type="fixed">
    <origin rpy="0 0 0" xyz="0 0 0.6"/>
    <parent link="robot_footprint"/>
    <child link="chassis"/>
  </joint>
  <link name="chassis">
    <pose>0 0 0.1 0 0 0</pose>
    <inertial>
      <mass value="20.0"/>
      <origin rpy=" 0 0 0" xyz="0.0 0 0"/>
      <inertia ixx="0.1" ixy="0" ixz="0" iyy="0.1" iyz="0" izz="0.1"/>
    </inertial>
    <collision name="collision">
      <origin rpy=" 0 0 0" xyz="0 0 0"/>
      <geometry>
        <box size=".95 .6 .05"/>
      </geometry>
    </collision>
    <visual name="chassis_visual">
      <origin rpy=" 0 0 0" xyz="0 0 0"/>
      <geometry>
        <box size=".95 .6 .05"/>
      </geometry>
    </visual>
  </link>
  <link name="box">
    <inertial>
      <mass value="20.0"/>
      <origin rpy=" 0 0 0" xyz="0.0 0 0"/>
      <inertia ixx="0.1" ixy="0" ixz="0" iyy="0.1" iyz="0" izz="0.1"/>
    </inertial>
    <collision name="collision">
      <origin rpy=" 0 0 0" xyz="0 0 0.05"/>
      <geometry>
        <box size=".7 .5 .35"/>
      </geometry>
    </collision>
    <visual name="box_visual">
      <origin rpy=" 0 0 0" xyz="0 0 0.05"/>
      <geometry>
        <box size=".7 .5 .35"/>
      </geometry>
    </visual>
  </link>
  <joint name="box_joint" type="fixed">
    <origin rpy="0 0 0" xyz="0 0 -0.25"/>
    <parent link="chassis"/>
    <child link="box"/>
  </joint>
  <link name="front_right_wheel">
    <visual name="front_right_wheel_visual">
      <origin rpy=" 0 1.5707 1.5707" xyz="0.0 0 0"/>
      <geometry>
        <cylinder length="0.05" radius="0.1"/>
      </geometry>
    </visual>
    <collision>
      <origin rpy=" 0 1.5707 1.5707" xyz="0.0 0 0"/>
      <geometry>
        <cylinder length="0.05" radius="0.1"/>
      </geometry>
    </collision>
    <inertial>
      <origin rpy=" 0 1.5707 1.5707" xyz="0.0 0 0"/>
      <mass value="5.0"/>
      <inertia ixx="0.1" ixy="0" ixz="0" iyy="0.1" iyz="0" izz="0.1"/>
    </inertial>
  </link>
  <link name="back_right_wheel">
    <visual name="back_right_wheel_visual">
      <origin rpy=" 0 1.5707 1.5707" xyz="0.0 0 0"/>
      <geometry>
        <cylinder length="0.05" radius="0.2"/>
      </geometry>
    </visual>
    <collision>
      <origin rpy=" 0 1.5707 1.5707" xyz="0.0 0 0"/>
      <geometry>
        <cylinder length="0.05" radius="0.2"/>
      </geometry>
    </collision>
    <inertial>
      <origin rpy=" 0 1.5707 1.5707" xyz="0.0 0 0"/>
      <mass value="0.5"/>
      <inertia ixx="0.1" ixy="0" ixz="0" iyy="0.1" iyz="0" izz="0.1"/>
    </inertial>
  </link>
  <link name="back_right_wheel_cover">
    <visual name="back_right_wheel_cover_visual">
      <origin rpy=" 0 1.5707 1.5707" xyz="0.0 0 0"/>
      <geometry>
        <cylinder length="0.01" radius="0.15"/>
      </geometry>
    </visual>
    <collision>
      <origin rpy=" 0 1.5707 1.5707" xyz="0.0 0 0"/>
      <geometry>
        <cylinder length="0.01" radius="0.15"/>
      </geometry>
    </collision>
    <inertial>
      <origin rpy=" 0 1.5707 1.5707" xyz="0.0 0 0"/>
      <inertia ixx="0.1" ixy="0" ixz="0" iyy="0.1" iyz="0" izz="0.1"/>
      <mass value="0.01"/>
    </inertial>
  </link>
  <joint name="front_right_wheel_joint" type="continuous">
    <axis rpy="0 0 0" xyz="0 1 0"/>
    <dynamics damping="1.0" friction="1.0"/>
    <parent link="chassis"/>
    <child link="front_right_wheel"/>
    <origin rpy="0 0 0" xyz="0.3 -0.3 -0.35"/>
  </joint>
  <joint name="back_right_wheel_joint" type="continuous">
    <axis rpy="0 0 0" xyz="0 1 0"/>
    <dynamics damping="1.0" friction="1.0"/>
    <parent link="chassis"/>
    <child link="back_right_wheel"/>
    <origin rpy="0 0 0" xyz="-0.25 -0.3 -0.25"/>
  </joint>
  <joint name="back_right_wheel_cover_joint" type="continuous">
    <axis rpy="0 0 0" xyz="0 1 0"/>
    <dynamics damping="1.0" friction="1.0"/>
    <parent link="back_right_wheel"/>
    <child link="back_right_wheel_cover"/>
    <origin rpy="0 0 0" xyz="0 -0.025 0"/>
  </joint>
  <link name="front_left_wheel">
    <visual name="front_left_wheel_visual">
      <origin rpy=" 0 1.5707 1.5707" xyz="0.0 0 0"/>
      <geometry>
        <cylinder length="0.05" radius="0.1"/>
      </geometry>
    </visual>
    <collision>
      <origin rpy=" 0 1.5707 1.5707" xyz="0.0 0 0"/>
      <geometry>
        <cylinder length="0.05" radius="0.1"/>
      </geometry>
    </collision>
    <inertial>
      <origin rpy=" 0 1.5707 1.5707" xyz="0.0 0 0"/>
      <mass value="5.0"/>
      <inertia ixx="0.1" ixy="0" ixz="0" iyy="0.1" iyz="0" izz="0.1"/>
    </inertial>
  </link>
  <link name="back_left_wheel_cover">
    <visual name="back_left_wheel_cover_visual">
      <origin rpy=" 0 1.5707 1.5707" xyz="0.0 0 0"/>
      <geometry>
        <cylinder length="0.01" radius="0.15"/>
      </geometry>
    </visual>
    <collision>
      <origin rpy=" 0 1.5707 1.5707" xyz="0.0 0 0"/>
      <geometry>
        <cylinder length="0.01" radius="0.15"/>
      </geometry>
    </collision>
    <inertial>
      <origin rpy=" 0 1.5707 1.5707" xyz="0.0 0 0"/>
      <inertia ixx="0.1" ixy="0" ixz="0" iyy="0.1" iyz="0" izz="0.1"/>
      <mass value="0.01"/>
    </inertial>
  </link>
  <link name="back_left_wheel">
    <visual name="back_left_wheel_visual">
      <origin rpy=" 0 1.5707 1.5707" xyz="0.0 0 0"/>
      <geometry>
        <cylinder length="0.05" radius="0.2"/>
      </geometry>
    </visual>
    <collision>
      <origin rpy=" 0 1.5707 1.5707" xyz="0.0 0 0"/>
      <geometry>
        <cylinder length="0.05" radius="0.2"/>
      </geometry>
    </collision>
    <inertial>
      <origin rpy=" 0 1.5707 1.5707" xyz="0.0 0 0"/>
      <inertia ixx="0.1" ixy="0" ixz="0" iyy="0.1" iyz="0" izz="0.1"/>
      <mass value="0.5"/>
    </inertial>
  </link>
  <joint name="front_left_wheel_joint" type="continuous">
    <axis rpy="0 0 0" xyz="0 1 0"/>
    <dynamics damping="1.0" friction="1.0"/>
    <parent link="chassis"/>
    <child link="front_left_wheel"/>
    <origin rpy="0 0 0" xyz="0.3 0.3 -0.35"/>
  </joint>
  <joint name="back_left_wheel_joint" type="continuous">
    <axis rpy="0 0 0" xyz="0 1 0"/>
    <dynamics damping="1.0" friction="1.0"/>
    <parent link="chassis"/>
    <child link="back_left_wheel"/>
    <origin rpy="0 0 0" xyz="-0.25 0.3 -0.25"/>
  </joint>
  <joint name="back_left_wheel_cover_joint" type="continuous">
    <axis rpy="0 0 0" xyz="0 1 0"/>
    <parent link="back_left_wheel"/>
    <child link="back_left_wheel_cover"/>
    <origin rpy="0 0 0" xyz="0 0.025 0"/>
  </joint>
  <!-- *********************** IMU SENSOR SETUP **********************************  -->
  <joint name="imu_joint" type="fixed">
    <parent link="chassis"/>
    <child link="imu_link"/>
    <origin rpy="0 0 0" xyz="0.10 0 0.05"/>
  </joint>
  <!-- *********************** IMU SENSOR SETUP **************************  -->
  <link name="imu_link"/>
  <!-- *********************** GPS SETUP **********************************  -->
  <joint name="gps_joint" type="fixed">
    <parent link="chassis"/>
    <child link="gps_link"/>
    <origin rpy="0 0 0" xyz="0.10 0 0.05"/>
  </joint>
  <!-- *********************** GPS SETUP *********************************  -->
  <link name="gps_link"/>
  <!-- *********************** LIDAR SETUP **********************************  -->
  <joint name="lidar_joint" type="fixed">
    <parent link="chassis"/>
    <child link="lidar_link"/>
    <origin rpy="0 0 0" xyz="0.215 0 0.13"/>
  </joint>
  <link name="lidar_link">
    <collision>
      <origin rpy="0 0 0" xyz="0 0 0"/>
      <geometry>
        <cylinder length="0.18" radius="0.0508"/>
      </geometry>
    </collision>
    <visual>
      <origin rpy="0 0 0" xyz="0 0 0"/>
      <geometry>
        <cylinder length="0.18" radius="0.0508"/>
      </geometry>
      <material name="Black">
        <color rgba="0.0 0.0 0.0 1.0"/>
      </material>
    </visual>
    <inertial>
      <mass value="0.114"/>
      <origin rpy="0 0 0" xyz="0 0 0"/>
      <inertia ixx="0.001" ixy="0" ixz="0" iyy="0.001" iyz="0" izz="0.001"/>
    </inertial>
  </link>
  <gazebo reference="chassis">
    <material>Gazebo/White</material>
  </gazebo>
  <gazebo reference="box">
    <material>Gazebo/Grey</material>
  </gazebo>
  <gazebo reference="front_right_wheel">
    <material>Gazebo/Black</material>
  </gazebo>
  <gazebo reference="front_left_wheel">
    <material>Gazebo/Black</material>
  </gazebo>
  <gazebo reference="back_right_wheel">
    <material>Gazebo/Black</material>
  </gazebo>
  <gazebo reference="back_left_wheel">
    <material>Gazebo/Black</material>
  </gazebo>
  <gazebo reference="back_right_wheel_cover">
    <material>Gazebo/Grey</material>
  </gazebo>
  <gazebo reference="back_left_wheel_cover">
    <material>Gazebo/Grey</material>
  </gazebo>
</robot>
